Workbook

Sheet Resumo
A1: Distribuição de Prospects por Vendedor
A3: Critério de distribuição: round-robin (intercalado) para balancear UF e setor entre os 4 vendedores.
A5: Vendedor | B5: Qtd. Empresas | C5: Faturamento Total Presumido (R$) | D5: Total Funcionários
A6: Vendedor 1 | B6: =COUNTA(SANDRA!A5:A100) -> 47 | C6: =SUM(SANDRA!E5:E100) -> 10545619542 | D6: =SUM(SANDRA!G5:G100) -> 11240
A7: Vendedor 2 | B7: =COUNTA(ADRIANA!A5:A100) -> 47 | C7: =SUM(ADRIANA!E5:E100) -> 10435272362 | D7: =SUM(ADRIANA!G5:G100) -> 11477
A8: Vendedor 3 | B8: =COUNTA(GISLAINE!A5:A100) -> 47 | C8: =SUM(GISLAINE!E5:E100) -> 10368800237 | D8: =SUM(GISLAINE!G5:G100) -> 12736
A9: Vendedor 4 | B9: =COUNTA(EDUARDO!A5:A100) -> 46 | C9: =SUM(EDUARDO!E5:E100) -> 10152317542 | D9: =SUM(EDUARDO!G5:G100) -> 14094
A10: TOTAL | B10: =SUM(B6:B9) -> 187 | C10: =SUM(C6:C9) -> 41502009683 | D10: =SUM(D6:D9) -> 49547
A13: Distribuição por UF
A14: UF | B14: Vendedor 1 | C14: Vendedor 2 | D14: Vendedor 3 | E14: Vendedor 4 | F14: Total
A15: AC | B15: 0 | C15: 1 | D15: 0 | E15: 0 | F15: =SUM(B15:E15) -> 1
A16: AM | B16: 0 | C16: 0 | D16: 0 | E16: 2 | F16: =SUM(B16:E16) -> 2
A17: BA | B17: 3 | C17: 0 | D17: 1 | E17: 0 | F17: =SUM(B17:E17) -> 4
A18: CE | B18: 1 | C18: 0 | D18: 2 | E18: 0 | F18: =SUM(B18:E18) -> 3
A19: DF | B19: 1 | C19: 0 | D19: 0 | E19: 0 | F19: =SUM(B19:E19) -> 1
A20: ES | B20: 1 | C20: 2 | D20: 4 | E20: 1 | F20: =SUM(B20:E20) -> 8
A21: GO | B21: 2 | C21: 0 | D21: 1 | E21: 1 | F21: =SUM(B21:E21) -> 4
A22: MG | B22: 10 | C22: 5 | D22: 4 | E22: 6 | F22: =SUM(B22:E22) -> 25
A23: MS | B23: 0 | C23: 1 | D23: 0 | E23: 0 | F23: =SUM(B23:E23) -> 1
A24: MT | B24: 0 | C24: 1 | D24: 1 | E24: 0 | F24: =SUM(B24:E24) -> 2
A25: PE | B25: 0 | C25: 0 | D25: 0 | E25: 1 | F25: =SUM(B25:E25) -> 1
A26: PI | B26: 0 | C26: 0 | D26: 0 | E26: 1 | F26: =SUM(B26:E26) -> 1
... A32: SP | B32: 16 | C32: 16 | D32: 19 | E32: 17 | F32: =SUM(B32:E32) -> 68
A34: Dica: cada aba já vem com filtro automático, cabeçalho congelado e as 3 primeiras colunas fixadas para facilitar a navegação.

Sheet SANDRA
A1: Carteira de Prospects — Vendedor 1
A2: Total de empresas: 47 | Porte: GRANDE | Fonte: Base de prospecção
A4: CNPJ | B4: Razão Social | C4: Nome Fantasia | D4: Porte | E4: Faturamento Presumido (R$) | F4: Capital Social (R$) | G4: Qtd. Funcionários | H4: Score | I4: Classificação de Risco | J4: Situação Cadastral | K4: CNAE | L4: Atividade Principal | M4: Data Abertura | N4: Qtd. Filiais | O4: Logradouro | P4: Nº | Q4: Complemento | R4: Bairro | S4: Cidade | T4: UF | U4: CEP | V4: DDD 1 | W4: Telefone 1 | X4: Tipo 1 | Y4: DDD 2 | Z4: Telefone 2 | AA4: Tipo 2 | AB4: DDD 3 | AC4: Telefone 3 | AD4: Tipo 3 | AE4: DDD 4 | AF4: Telefone 4 | AG4: Tipo 4 | AH4: E-mail 1 | AI4: E-mail 2 | AJ4: E-mail 3 | AK4: Sócio 1 | AL4: Cargo Sócio 1 | AM4: DDD Sócio 1 | AN4: Tel. Sócio 1 | AO4: Sócio 2 | AP4: Cargo Sócio 2 | AQ4: DDD Sócio 2 | AR4: Tel. Sócio 2 | AS4: Sócio 3 | AT4: Cargo Sócio 3 | AU4: DDD Sócio 3 | AV4: Tel. Sócio 3 | AW4: CNAEs Secundários | AX4: Inscrição Estadual | AY4: Flag DAU
A5: 59.105.262/0001-63 | B5: TRANSAUTO TRANSPORTES ESPECIALIZADOS DE AUTOMOVEIS S A | D5: GRANDE | E5: 472761491 | F5: 100000000 | G5: 70 | H5: 914 | I5: RISCO MUITO BAIXO | J5: ATIVA | K5: 4930202 | L5: Transporte rodoviário de carga, exceto produtos perigosos e mudanças, intermunicipal, interestadual e internacional | M5: 7/20/1966 | N5: 12 | O5: SENADOR VERGUEIRO | P5: 4600 | R5: RUDGE RAMOS | S5: SAO BERNARDO DO CAMPO | T5: SP | U5: 9604000 | V5: 11 | W5: 930660337 | X5: Celular | Y5: 11 | Z5: 956962202 | AA5: Celular | AB5: 11 | AC5: 963888459 | AD5: Celular | AE5: 11 | AF5: 43663400 | AG5: Fixo | AH5: CONTAB@TRANSAUTO.COM.BR | AI5: ADRIANA@TRANSAUTO.COM.BR | AJ5: ALEXANDRE@TRANSAUTO.COM.BR | AK5: ANA LUIZA MENEZES DE GOES | AL5: DIRETOR | AM5: 11 | AN5: 992041313 | AO5: ERYX DE OLIVEIRA | AP5: DIRETOR | AQ5: 11 | AR5: 991834832 | AW5: 4520007-Serviços de instalação, manutenção e reparação de acessórios para veículos automotores\4930201-Transporte rodoviário de carga, exceto produtos perigosos e mudanças, municipal\5229002-Serviços de reboque de veículos\ | AX5: 635.031.050.113 | AY5: N
A6: 01.934.441/0001-23 | B6: TRANSPORTES SARZEDO LTDA | D6: GRANDE | E6: 455830534 | F6: 30500000 | G6: 2069 | H6: 940 | I6: RISCO MUITO BAIXO | J6: ATIVA | K6: 4930201 | L6: Transporte rodoviário de carga, exceto produtos perigosos e mudanças, municipal | M6: 6/24/1997 | N6: 1 | O6: CAMPOS ELISIOS | P6: 371 | R6: BRASILIA | S6: SARZEDO | T6: MG | U6: 32450000 | V6: 31 | W6: 971857584 | X6: Celular | Y6: 31 | Z6: 998885048 | AA6: Celular | AB6: 31 | AC6: 971108927 | AD6: Celular | AE6: 31 | AF6: 35778749 | AG6: Fixo | AH6: CACAMBAS.ATERRO@TSLSOLUCOES.COM.BR | AK6: JOSE DONIZETE DE SOUZA MAIA | AL6: SOCIO ADMINISTRADOR | AM6: 31 | AN6: 999672488 | AO6: JOAO PAULO MOREIRA DE SOUSA | AP6: ADMINISTRADOR | AQ6: 31 | AR6: 998885048 | AS6: EDUARDO MENDES DE SOUSA MAIA | AT6: ADMINISTRADOR | AU6: 31 | AV6: 991587550 | AW6: 3811400-Coleta de resíduos não perigosos\4313400-Obras de terraplenagem\4319300-Serviços de preparação do terreno não especificados anteriormente\4929902-Transporte rodoviário coletivo de passageiros, sob regime de fretamento, intermunicipal, interestadual e internacional\4930202-Transporte rodoviário de carga, exceto produtos perigosos e mudanças, intermunicipal, interestadual e internacional\4930203-Transporte rodoviário de produtos perigosos\5212500-Carga e descarga\7739099-Aluguel de outras máquinas e equipamentos comerciais e industriais não especificados anteriormente, sem operador\7820500-Locação de mão de obra temporária\8129000-Atividades de limpeza não especificadas anteriormente | AX6: 850041085.00-38 | AY6: N
A7: 11.727.497/0001-60 | B7: NATURAVES INDUSTRIA E COMERCIO DE ALIMENTOS LTDA | D7: GRANDE | E7: 419981320 | F7: 54362847 | G7: 607 | H7: 606 | I7: RISCO BAIXO | J7: ATIVA | K7: 1012101 | L7: Abate de aves | M7: 3/16/2010 | N7: 1 | O7: RUY BARBOSA 479 | Q7: FAZENDA RESPLENDOR | R7: CENTRO | S7: EUNAPOLIS | T7: BA | U7: 45820970 | V7: 73 | W7: 999551456 | X7: Celular | Y7: 73 | Z7: 998681454 | AA7: Celular | AB7: 73 | AC7: 998712612 | AD7: Celular | AE7: 73 | AF7: 31662450 | AG7: Fixo | AH7: FISCAL2@NATURAVES.COM.BR | AK7: JUSCIMAR MODENEZI DE ALMEIDA | AL7: ADMINISTRADOR | AM7: 73 | AN7: 999851115 | AO7: CLEOMAR MODENEZI DE ALMEIDA | AP7: ADMINISTRADOR | AQ7: 73 | AR7: 981591409 | AS7: CESCONETTO E FILHOS PARTICIPACOES SOCIETARIAS LTDA | AT7: SOCIO | AU7: 73 | AV7: 31662450 | AW7: 0111302-Cultivo de milho\0155501-Criação de frangos para corte\0155502-Produção de pintos de um dia\1013901-Fabricação de produtos de carne\1013902-Preparação de subprodutos do abate\1066000-Fabricação de alimentos para animais\4623109-Comércio atacadista de alimentos para animais\4634602-Comércio atacadista de aves abatidas e derivados\4639701-Comércio atacadista de produtos alimentícios em geral\4930202-Transporte rodoviário de carga, exceto produtos perigosos e mudanças, intermunicipal, interestadual e internacional\5620101-Fornecimento de alimentos preparados preponderantemente para empresas\ | AX7: 086.309.978 | AY7: N
A8: 02.326.750/0001-83 | B8: INTERCAST S/A | D8: GRANDE | E8: 408374455 | F8: 14350450 | G8: 416 | H8: 900 | I8: RISCO MUITO BAIXO | J8: ATIVA | K8: 2451200 | L8: Fundição de ferro e aço | M8: 1/21/1998 | N8: 0 | O8: MG-050 | P8: KM 92 | R8: DISTRITO INDUSTRIAL | S8: ITAUNA | T8: MG | U8: 35681750 | V8: 37 | W8: 998566598 | X8: Celular | Y8: 37 | Z8: 998248452 | AA8: Celular | AB8: 37 | AC8: 998765162 | AD8: Celular | AE8: 37 | AF8: 32497040 | AG8: Fixo | AH8: FERNANDA@INTERCAST.COM.BR | AI8: INTERCAST@INTERCAST.COM.BR | AJ8: LILIAN@INTERCAST.COM.BR | AK8: CASSIO MOREIRA MACHADO | AL8: PRESIDENTE | AM8: 37 | AN8: 991214401 | AO8: SAMUEL NOGUEIRA RABELO DE MELO | AP8: DIRETOR | AW8: 2543800-Fabricação de ferramentas\3319800-Manutenção e reparação de equipamentos e produtos não especificados anteriormente\4663000-Comércio atacadista de máquinas e equipamentos para uso industrial, partes e peças\ | AX8: 338726365.00-33 | AY8: N
A9: 19.749.936/0001-48 | B9: GSL METALURGICA S/A | D9: GRANDE | E9: 391025934 | F9: 15000000 | G9: 316 | H9: 917 | I9: RISCO MUITO BAIXO | J9: ATIVA | K9: 2511000 | L9: Fabricação de estruturas metálicas | M9: 8/11/1977 | N9: 2 | O9: ENGENHEIRO SERGIO MACULAN | P9: 120 | R9: DISTRITO INDUSTRIAL SIMAO DA CUNHA | S9: SABARA | T9: MG | U9: 34735022 | V9: 31 | W9: 995330574 | X9: Celular | Y9: 31 | Z9: 971358821 | AA9: Celular | AB9: 31 | AC9: 999589015 | AD9: Celular | AE9: 31 | AF9: 36793100 | AG9: Fixo | AH9: GSL@GSL.COM.BR | AI9: COMPRAS2@GSL.COM.BR | AJ9: QUALIDADE@GSL.COM.BR | AK9: FABIANO DE SOUZA BATISTA | AL9: CONSELHEIRO DE ADMINISTRACAO | AM9: 31 | AN9: 984043997 | AO9: DANIEL CARVALHO MARTINS | AP9: DIRETOR | AQ9: 31 | AR9: 992750300 | AS9: JANINE CARVALHO MARTINS | AT9: CONSELHEIRO DE ADMINISTRACAO | AU9: 81 | AV9: 991417313 | AW9: 2539002-Serviços de tratamento e revestimento em metais\4292801-Montagem de estruturas metálicas\7112000-Serviços de engenharia\ | AX9: 578260161.00-70 | AY9: N
A10: 09.078.935/0001-65 | B10: STARNAV SERVICOS MARITIMOS LTDA. | D10: GRANDE | E10: 384199059 | F10: 247393395 | G10: 651 | H10: 464 | I10: RISCO MÉDIO | J10: ATIVA | K10: 5030101 | L10: Navegação de apoio marítimo | M10: 9/25/2007 | N10: 5 | O10: CESAR AUGUSTO DALSOQUIO | P10: 4500 | Q10: SALAA | R10: SALSEIROS | S10: ITAJAI | T10: SC | U10: 88311500 | V10: 22 | W10: 996161482 | X10: Celular | Y10: 22 | Z10: 996161655 | AA10: Celular | AB10: 22 | AC10: 999211094 | AD10: Celular | AE10: 47 | AF10: 21038561 | AG10: Fixo | AH10: WKBRA@DETROIT.CL | AK10: DETROIT UK INTERNATIONAL LLP | AL10: SOCIO PESSOA JURIDICA DOMICILIADO NO EXTERIOR | AO10: JULIANO ZIMMERMANN DE FREITAS | AP10: ADMINISTRADOR | AQ10: 47 | AR10: 999279442 | AW10: 4669999-Comércio atacadista de outras máquinas e equipamentos não especificados anteriormente, partes e peças\5011401-Transporte marítimo de cabotagem - Carga\5011402-Transporte marítimo de cabotagem - Passageiros\5012201-Transporte marítimo de longo curso - Carga\5012202-Transporte marítimo de longo curso - Passageiros\5021102-Transporte por navegação interior de carga, intermunicipal, interestadual e internacional, exceto travessia\5022002-Transporte por navegação interior de passageiros em linhas regulares, intermunicipal, interestadual e internacional, exceto travessia\5030102-Navegação de apoio portuário\5030103-Serviço de rebocadores e empurradores\6462000-Holdings de instituições não financeiras\6463800-Outras sociedades de participação, exceto holdings\7719501-Locação de embarcações sem tripulação, exceto para finsrecreativos | AX10: 255858620 | AY10: N
A11: 04.731.861/0001-09 | B11: INTERALLI GRAOS TERMINAIS S.A | D11: GRANDE | E11: 368955710 | F11: 60116176 | G11: 188 | H11: 930 | I11: RISCO MUITO BAIXO | J11: ATIVA | K11: 5231102 | L11: Atividades do Operador Portuário | M11: 10/22/2001 | N11: 4 | O11: PORTUARIA | R11: DOM PEDRO II | S11: PARANAGUA | T11: PR | U11: 83221570 | V11: 31 | W11: 984631182 | X11: Celular | Y11: 41 | Z11: 32210707 | AA11: Fixo | AH11: CONTADOR1@INTERALLI.COM.BR | AI11: ANGELA@INTERALLI.COM.BR | AJ11: ANDERSON@INTERALLI.COM.BR | AK11: CRISTIANO SLAVIERO FUMAGALLI | AL11: DIRETOR | AM11: 43 | AN11: 999579325 | AO11: FELIPE SLAVIERO FUMAGALLI | AP11: DIRETOR | AQ11: 43 | AR11: 999741354 | AS11: FABRICIO SLAVIERO FUMAGALLI | AT11: DIRETOR | AU11: 66 | AV11: 999540930 | AW11: 5211701-Armazéns gerais - emissão de warrant\5232000-Atividades de agenciamento marítimo\5250801-Comissaria de despachos\5250803-Agenciamento de cargas, exceto para o transporte marítimo | AX11: 90529181-51 | AY11: N
A12: 17.578.354/0001-10 | B12: ITESAPAR FUNDICAO LTDA | C12: ITESAPAR FUNDICAO | D12: GRANDE | E12: 357152613 | F12: 20000000 | G12: 26 | H12: 206 | I12: RISCO ALTO | J12: ATIVA | K12: 2452100 | L12: Fundição de metais não ferrosos e suas ligas | M12: 2/7/2013 | N12: 0 | O12: PE ANCHIETA | P12: 112 | Q12: LT 12 LT 12 112 | R12: VL VIDA | S12: PALMEIRA | T12: PR | U12: 84130000 | V12: 42 | W12: 32528536 | X12: Fixo | AH12: CONTABIL@ITESAPAR.COM.BR | AI12: DIRETORIA@ITESA.COM.BR | AJ12: ADIR.SANTOS@ITESAPAR.COM.BR | AK12: MARCELO RIBEIRO | AL12: SOCIO-ADMINISTRADOR | AM12: 11 | AN12: 959501724 | AW12: 2539001-Serviços de usinagem, torneiria e solda\7739001-Aluguel de máquinas e equipamentos para extração de minérios e petróleo, sem operador | AX12: 90621463-60 | AY12: S
A13: 04.535.453/0001-73 | B13: BRASCERAS S.A. INDUSTRIA E COMERCIO | C13: GEQUIMICA INDUSTRIA E COMERCIO | D13: GRANDE | E13: 333829029 | F13: 32449000 | G13: 32 | H13: 967 | I13: RISCO MUITO BAIXO | J13: ATIVA | K13: 1921700 | L13: Fabricação de produtos do refino de petróleo | M13: 6/21/2001 | N13: 3 | O13: COPACABANA | P13: 190 | Q13: SALA 801 E 802 | R13: DEZOITO DO FORTE EMPRESARIAL/ALPHAVILLE. | S13: BARUERI | T13: SP | U13: 6472001 | V13: 11 | W13: 41338111 | X13: Fixo | AH13: ANDREIA.ZEBELLINI@GEQUIMICA.COM.BR | AI13: CLELIO@GEQUIMICA.COM.BR | AJ13: ADILSON.XAVIER@GEQUIMICA.COM.BR | AK13: KLEBER REIMBERG GUTSCHOW | AL13: PRESIDENTE | AM13: 11 | AN13: 983549171 | AO13: GISELE CIRILO SILVESTRE | AP13: DIRETOR | AQ13: 11 | AR13: 999562014 | AW13: 2099199-Fabricação de outros produtos químicos não especificados anteriormente\4612500-Representantes comerciais e agentes do comércio de combustíveis, minerais, produtos siderúrgicos e químicos\4684299-Comércio atacadista de outros produtos químicos e petroquímicos não especificados anteriormente\4693100-Comércio atacadista de mercadorias em geral, sem predominância de alimentos ou de insumos agropecuários\4930201-Transporte rodoviário de carga, exceto produtos perigosos e mudanças, municipal\4930202-Transporte rodoviário de carga, exceto produtos perigosos e mudanças, intermunicipal, interestadual e internacional\5250803-Agenciamento de cargas, exceto para o transporte marítimo\7719599-Locação de outros meios de transporte não especificados anteriormente, sem condutor\8211300-Serviços combinados de escritório e apoio administrativo\ | AX13: 90247455-27 | AY13: N
A14: 60.319.985/0001-44 | B14: JOMED TRANSPORTES E LOGISTICA S/A | D14: GRANDE | E14: 327762506 | F14: 13153280 | G14: 235 | H14: 864 | I14: RISCO MUITO BAIXO | J14: ATIVA | K14: 4930202 | L14: Transporte rodoviário de carga, exceto produtos perigosos e mudanças, intermunicipal, interestadual e internacional | M14: 3/31/1989 | N14: 9 | O14: SISA | P14: 261 | R14: CIDADE INDUSTRIAL SATELITE DE SAO PAULO | S14: GUARULHOS | T14: SP | U14: 7221030 | V14: 27 | W14: 974001210 | X14: Celular | Y14: 11 | Z14: 971965330 | AA14: Celular | AB14: 11 | AC14: 49668215 | AD14: Fixo | AH14: SIDNEI.ALVES@JOMEDLOG.COM.BR | AI14: COMERCIAL@JOMEDLOG.COM.BR | AK14: ODAIR BRAGA GARRIDO | AL14: TITULAR PESSOA FISICA RESIDENTE OU DOMICILIADO NO BRASIL | AM14: 11 | AN14: 940321440 | AO14: JOCELIA DE JESUS CAMPOS | AP14: DIRETOR | AQ14: 27 | AR14: 997236372 | AW14: 4930201-Transporte rodoviário de carga, exceto produtos perigosos e mudanças, municipal\4930203-Transporte rodoviário de produtos perigosos\5211701-Armazéns gerais - emissão de warrant\5211799-Depósitos de mercadorias para terceiros, exceto armazéns gerais e guarda-móveis\5212500-Carga e descarga\5250805-Operador de transporte multimodal - OTM\5320201-Serviços de malote não realizados pelo Correio Nacional\5320202-Serviços de entrega rápida\7719599-Locação de outros meios de transporte não especificados anteriormente, sem condutor\ | AX14: 796.529.849.112 | AY14: N
A15: 02.462.805/0001-82 | B15: FM LOGISTIC DO BRASIL OPERACOES DE LOGISTICA LTDA. | D15: GRANDE | E15: 303447574 | F15: 87004818 | G15: 22 | H15: 290 | I15: RISCO ALTO | J15: ATIVA | K15: 5211701 | L15: Armazéns gerais - emissão de warrant | M15: 3/6/1998 | N15: 9 | O15: ANHANGUERA | Q15: KM26 421 PREDIO 1 SALA1 | R15: JARDIM JARAGUA | S15: SAO PAULO | T15: SP | U15: 5275000 | V15: 31 | W15: 984358933 | X15: Celular | Y15: 31 | Z15: 984358691 | AA15: Celular | AB15: 31 | AC15: 984346784 | AD15: Celular | AE15: 11 | AF15: 21099400 | AG15: Fixo | AH15: CPFISCAL@FMLOGISTIC.COM.BR | AK15: FM LOGISTIC SERVICES | AL15: SOCIO PESSOA JURIDICA DOMICILIADO NO EXTERIOR | AO15: FM LOGISTIC CORPORATE | AP15: SOCIO PESSOA JURIDICA DOMICILIADO NO EXTERIOR | AS15: RONALDO FERNANDES DA SILVA | AT15: ADMINISTRADOR | AU15: 19 | AV15: 981377125 | AW15: 4930202-Transporte rodoviário de carga, exceto produtos perigosos e mudanças, intermunicipal, interestadual e internacional\8292000-Envasamento e empacotamento sob contrato | AX15: 142.238.168.114 | AY15: N
A16: 39.397.682/0001-53 | B16: BUSATO - TRANSPORTES E LOCACOES LTDA | D16: GRANDE | E16: 287327513 | F16: 300000 | G16: 619 | H16: 861 | I16: RISCO MUITO BAIXO | J16: ATIVA | K16: 4930202 | L16: Transporte rodoviário de carga, exceto produtos perigosos e mudanças, intermunicipal, interestadual e internacional | M16: 2/3/1993 | N16: 1 | O16: GAIVOTA | P16: 1640 | R16: NOVO HORIZONTE | S16: SERRA | T16: ES | U16: 29163322 | V16: 31 | W16: 997681925 | X16: Celular | Y16: 27 | Z16: 996168132 | AA16: Celular | AB16: 27 | AC16: 992551869 | AD16: Celular | AE16: 27 | AF16: 32162008 | AG16: Fixo | AH16: COMERCIAL@BUSATOTRANSPORTES.COM.BR | AI16: BUSATO.CONSTRUTORA@TERRA.COM.BR | AK16: GENEZIO BUSATO | AL16: SOCIO | AM16: 27 | AN16: 998314777 | AO16: EDNO BUSATO | AP16: SOCIO | AQ16: 27 | AR16: 999714900 | AS16: FERNANDO BUSATO | AT16: SOCIO ADMINISTRADOR | AU16: 27 | AV16: 996908044 | AW16: 3600602-Distribuição de água por caminhões\3811400-Coleta de resíduos não perigosos\3812200-Coleta de resíduos perigosos\4311801-Demolição de edifícios e outras estruturas\4399104-Serviços de operação e fornecimento de equipamentos para transporte e elevação de cargas e pessoas para uso em obras\4921301-Transporte rodoviário coletivo de passageiros, com itinerário fixo, municipal\4923002-Serviço de transporte de passageiros - locação de automóveis com motorista\4930201-Transporte rodoviário de carga, exceto produtos perigosos e mudanças, municipal\5212500-Carga e descarga\7711000-Locação de automóveis sem condutor\7719599-Locação de outros meios de transporte não especificados anteriormente, sem condutor\7732201-Aluguel de máquinas e equipamentos para construção sem operador, exceto andaimes\7739099-Aluguel de outras máquinas e equipamentos comerciais e industriais não especificados anteriormente, sem operador\ | AX16: 081.595.82-4 | AY16: N
A17: 13.892.216/0001-50 | B17: TORRES EOLICAS DO NORDESTE S/A | D17: GRANDE | E17: 282758528 | F17: 40255019 | H17: 947 | I17: RISCO MUITO BAIXO | J17: ATIVA | K17: 2511000 | L17: Fabricação de estruturas metálicas | M17: 6/28/2011 | N17: 1 | O17: DO CONTORNO | P17: 8269 | Q17: SALA 009 | R17: GUTIERREZ | S17: BELO HORIZONTE | T17: MG | U17: 30110059 | V17: 74 | W17: 999940869 | X17: Celular | Y17: 74 | Z17: 999712151 | AA17: Celular | AB17: 74 | AC17: 999752038 | AD17: Celular | AE17: 31 | AF17: 32906655 | AG17: Fixo | AH17: ILDA.AZEVEDO@AGNET.COM.BR | AK17: ANDRE DE RESENDE RODRIGUES | AL17: DIRETOR | AM17: 51 | AN17: 993246161 | AO17: JOSE ALBERTO TEIXEIRA DA SILVA | AP17: DIRETOR | AQ17: 12 | AR17: 996668080 | AS17: ARTHUR ARAUJO DE SOUZA | AT17: DIRETOR | AU17: 75 | AV17: 982144171 | AW17: 3319800-Manutenção e reparação de equipamentos e produtos não especificados anteriormente\4221902-Construção de estações e redes de distribuição de energia elétrica\5211799-Depósitos de mercadorias para terceiros, exceto armazéns gerais e guarda-móveis\7112000-Serviços de engenharia | AX17: 002161980.00-63 | AY17: N
A18: 49.316.524/0001-85 | B18: ROSARIAL ALIMENTOS S/A | C18: ROSARIAL ALIMENTOS | D18: GRANDE | E18: 275281111 | F18: 2060460 | G18: 61 | H18: 912 | I18: RISCO MUITO BAIXO | J18: ATIVA | K18: 1013901 | L18: Fabricação de produtos de carne | M18: 4/22/1970 | N18: 3 | O18: ESTM IBIUNA RIO DE UNA | P18: 777 | Q18: CXPST 16 | R18: RIO DE UNA | S18: IBIUNA | T18: SP | U18: 18150000 | V18: 15 | W18: 991255155 | X18: Celular | Y18: 15 | Z18: 991347427 | AA18: Celular | AB18: 15 | AC18: 996051756 | AD18: Celular | AE18: 15 | AF18: 32489791 | AG18: Fixo | AH18: EVANDRO@ROSARIAL.COM.BR | AI18: MARCO@ROSARIAL.COM.BR | AK18: MARCO AURELIO ROSSIT SILVA | AL18: PRESIDENTE | AM18: 15 | AN18: 991343638 | AO18: EVANDRO JESUS RIBEIRO | AP18: DIRETOR | AQ18: 15 | AR18: 991356968 | AW18: 4930201-Transporte rodoviário de carga, exceto produtos perigosos e mudanças, municipal\4930202-Transporte rodoviário de carga, exceto produtos perigosos e mudanças, intermunicipal, interestadual e internacional | AX18: 345.002.200.110 | AY18: S
A19: 04.754.815/0001-17 | B19: UP OFFSHORE APOIO MARITIMO LTDA | D19: MÉDIA | E19: 273016956 | F19: 212328705 | G19: 94 | H19: 645 | I19: RISCO BAIXO | J19: ATIVA | K19: 5030101 | L19: Navegação de apoio marítimo | M19: 9/12/2001 | N19: 1 | O19: DA GLORIA | P19: 344 | Q19: SALA401 PARTE SALA402 PARTE SALA403 PARTE SALA404 PARTE | R19: GLORIA | S19: RIO DE JANEIRO | T19: RJ | U19: 20241180 | V19: 21 | W19: 997735764 | X19: Celular | Y19: 21 | Z19: 967135148 | AA19: Celular | AB19: 21 | AC19: 971133230 | AD19: Celular | AE19: 21 | AF19: 21124500 | AG19: Fixo | AH19: MADAMES@SEACORMARINE.COM | AI19: ASETHI@UPOFFSHORE.COM.BR | AJ19: TI@UPOFFSHORE.COM.BR | AK19: OCEANPACT SERVICOS MARITIMOS S.A. | AL19: SOCIO | AM19: 21 | AN19: 30326700 | AO19: FLAVIO NOGUEIRA PINHEIRO DE ANDRADE | AP19: ADMINISTRADOR | AQ19: 85 | AR19: 997672472 | AS19: EDUARDO DE TOLEDO | AT19: ADMINISTRADOR | AU19: 11 | AV19: 999524185 | AW19: 0910600-Atividades de apoio à extração de petróleo e gás natural\4619200-Representantes comerciais e agentes do comércio de mercadorias em geral não especializado\5030102-Navegação de apoio portuário\5030103-Serviço de rebocadores e empurradores\5099899-Outros transportes aquaviários não especificados anteriormente\5232000-Atividades de agenciamento marítimo\6463800-Outras sociedades de participação, exceto holdings\7719501-Locação de embarcações sem tripulação, exceto para finsrecreativos | AX19: 77.344.993 | AY19: N
A20: 00.450.577/0001-03 | B20: CPC CONSTRUCOES E PROCESSOS CIENTIFICOS LTDA | D20: MÉDIA | E20: 265543364 | F20: 32000000 | G20: 329 | H20: 465 | I20: RISCO MÉDIO | J20: ATIVA | K20: 2511000 | L20: Fabricação de estruturas metálicas | M20: 7/6/1976 | N20: 2 | O20: SAAN QUADRA 2 | P20: 310 | Q20: ST ABAS NORTE | R20: ZONA INDUSTRIAL | S20: BRASILIA | T20: DF | U20: 70632200 | V20: 61 | W20: 993963184 | X20: Celular | Y20: 61 | Z20: 995568250 | AA20: Celular | AB20: 61 | AC20: 992554754 | AD20: Celular | AE20: 61 | AF20: 33610030 | AG20: Fixo | AH20: ANTONIO@CPCESTRUTURAS.COM.BR | AI20: ARMANDO@CPCESTRUTURAS.COM.BR | AJ20: CARLOS@CPCESTRUTURAS.COM.BR | AK20: RENATO MAIA PUPO | AL20: ADMINISTRADOR | AM20: 24 | AN20: 998593982 | AO20: RMP CONSTRUCOES E ENGENHARIA LTDA | AP20: SOCIO | AQ20: 61 | AR20: 35415643 | AW20: 2513600-Fabricação de obras de caldeiraria pesada\2521700-Fabricação de tanques, reservatórios metálicos e caldeiras para aquecimento central\2539001-Serviços de usinagem, torneiria e solda\2539002-Serviços de tratamento e revestimento em metais\2599302-Serviço de corte e dobra de metais\4110700-Incorporação de empreendimentos imobiliários\4120400-Construção de edifícios\4292801-Montagem de estruturas metálicas\4292802-Obras de montagem industrial\4329199-Outras obras de instalações em construções não especificadas anteriormente\6462000-Holdings de instituições não financeiras\6810201-Compra e venda de imóveis próprios\6810202-Aluguel de imóveis próprios\7112000-Serviços de engenharia | AX20: 0731759600176 | AY20: S
A21: 01.855.226/0001-37 | B21: SOLFACIL DISTRIBUIDORA INDUSTRIAL LTDA | C21: SOLFACIL DISTRIBUIDORA | D21: MÉDIA | E21: 260868277 | F21: 91045494 | G21: 109 | H21: 591 | I21: RISCO BAIXO | J21: ATIVA | K21: 2511000 | L21: Fabricação de estruturas metálicas | M21: 4/22/1997 | N21: 4 | O21: JOSE ALVES DOS SANTOS PASSOS | P21: 3064 | Q21: O GALP | R21: SAO MARTINHO | S21: TUBARAO | T21: SC | U21: 88708701 | V21: 48 | W21: 999913028 | X21: Celular | Y21: 48 | Z21: 998580002 | AA21: Celular | AB21: 48 | AC21: 984050627 | AD21: Celular | AE21: 48 | AF21: 36280258 | AG21: Fixo | AH21: CONTABILIDADE@SOLARINOVE.COM.BR | AI21: TURBOFERRO@TURBOFERRO.COM.BR | AJ21: BRAINER@TURBOFERRO.COM.BR | AK21: FABIO AUGUSTO BREDDA CARRARA | AL21: ADMINISTRADOR | AM21: 11 | AN21: 998009692 | AO21: GUILLAUME CHRISTIAN EMMANUEL TIRET | AP21: ADMINISTRADOR | AQ21: 11 | AR21: 944592654 | AS21: SOLFACIL PARTICIPACOES LTDA | AT21: SOCIO | AU21: 11 | AV21: 973987407 | AW21: 2542000-Fabricação de artigos de serralheria, exceto esquadrias\2610800-Fabricação de componentes eletrônicos\2710401-Fabricação de geradores de corrente contínua e alternada, peças e acessórios\2731700-Fabricação de aparelhos e equipamentos para distribuição e controle de energia elétrica\3329599-Instalação de outros equipamentos não especificados anteriormente\4292801-Montagem de estruturas metálicas\4669999-Comércio atacadista de outras máquinas e equipamentos não especificados anteriormente, partes e peças\4689399-Comércio atacadista especializado em outros produtos intermediários não especificados anteriormente\4742300-Comércio varejista de material elétrico\4930201-Transporte rodoviário de carga, exceto produtos perigosos e mudanças, municipal\4930202-Transporte rodoviário de carga, exceto produtos perigosos e mudanças, intermunicipal, interestadual e internacional\5211701-Armazéns gerais - emissão de warrant\5250801-Comissaria de despachos\5250803-Agenciamento de cargas, exceto para o transporte marítimo\5250804-Organização logística do transporte de carga\8211300-Serviços combinados de escritório e apoio administrativo | AX21: 253422817 | AY21: N
A22: 05.104.067/0001-90 | B22: GALAXIA MARITIMA S.A. | C22: GLX | D22: GRANDE | E22: 250330401 | F22: 7765000 | G22: 83 | H22: 542 | I22: RISCO BAIXO | J22: ATIVA | K22: 5030101 | L22: Navegação de apoio marítimo | M22: 5/22/2002 | N22: 1 | O22: ACAPULCO | P22: 24 | R22: CAVALEIROS | S22: MACAE | T22: RJ | U22: 27920150 | V22: 21 | W22: 984917897 | X22: Celular | Y22: 21 | Z22: 971785237 | AA22: Celular | AB22: 21 | AC22: 38048100 | AD22: Fixo | AH22: J.ALEXANDRE@GALAXIAMARITIMA.COM.BR | AI22: BIANCA.MARQUES@GALAXIAMARITIMA.COM.BR | AJ22: DAVID.ALVARENGA@GALAXIAMARITIMA.COM.BR | AK22: GERSON WAGNER PINHEIRO DE MORAES | AL22: DIRETOR | AM22: 21 | AN22: 996680563 | AO22: ANTONIO EDUARDO DE BARROS PINHEIRO | AP22: DIRETOR | AS22: THIAGO PALMIERI | AT22: DIRETOR | AU22: 21 | AV22: 974453613 | AW22: 5011401-Transporte marítimo de cabotagem - Carga\5012201-Transporte marítimo de longo curso - Carga\5030102-Navegação de apoio portuário\5232000-Atividades de agenciamento marítimo | AX22: 77.420.452 | AY22: S
A23: 58.673.450/0001-25 | B23: TAIPASTUR TRANSPORTES TURISTICOS LTDA | D23: GRANDE | E23: 226346985 | F23: 7340000 | G23: 239 | H23: 961 | I23: RISCO MUITO BAIXO | J23: ATIVA | K23: 4930202 | L23: Transporte rodoviário de carga, exceto produtos perigosos e mudanças, intermunicipal, interestadual e internacional | M23: 3/3/1988 | N23: 8 | O23: DEPUTADO CANTIDIO SAMPAIO | P23: 6557 | R23: VILA SOUZA | S23: SAO PAULO | T23: SP | U23: 2860001 | V23: 11 | W23: 21523500 | X23: Fixo | Y23: 11 | Z23: 993475924 | AA23: Celular | AB23: 11 | AC23: 989284271 | AD23: Celular | AE23: 11 | AF23: 989291421 | AG23: Celular | AH23: CONTABILIDADE@PICCOLOTUR.COM.BR | AK23: FERNANDO RUAS PICCOLO | AL23: SOCIO ADMINISTRADOR | AM23: 11 | AN23: 999435015 | AO23: EVANIR ROBERTO PICCOLO | AP23: SOCIO ADMINISTRADOR | AQ23: 31 | AR23: 995686556 | AW23: 4923002-Serviço de transporte de passageiros - locação de automóveis com motorista\4929901-Transporte rodoviário coletivo de passageiros, sob regime de fretamento, municipal\4929902-Transporte rodoviário coletivo de passageiros, sob regime de fretamento, intermunicipal, interestadual e internacional\4929904-Organização de excursões em veículos rodoviários próprios, intermunicipal, interestadual e internacional\4929999-Outros transportes rodoviários de passageiros não especificados anteriormente\4930201-Transporte rodoviário de carga, exceto produtos perigosos e mudanças, municipal\4930203-Transporte rodoviário de produtos perigosos\6462000-Holdings de instituições não financeiras\6463800-Outras sociedades de participação, exceto holdings\7711000-Locação de automóveis sem condutor\7719599-Locação de outros meios de transporte não especificados anteriormente, sem condutor\7739099-Aluguel de outras máquinas e equipamentos comerciais e industriais não especificados anteriormente, sem operador\7820500-Locação de mão de obra temporária\ | AX23: 112.326.797.110 | AY23: N
A24: 81.804.684/0001-86 | B24: TRANSPORTES E ARMAZENAGEM ZILLI LTDA | C24: TRANSZILLI EXPRESSO E LOGISTICA | D24: GRANDE | E24: 222712859 | F24: 139000000 | G24: 10 | H24: 913 | I24: RISCO MUITO BAIXO | J24: ATIVA | K24: 4930202 | L24: Transporte rodoviário de carga, exceto produtos perigosos e mudanças, intermunicipal, interestadual e internacional | M24: 4/17/1990 | N24: 26 | O24: BR-153 | P24: SN | Q24: QUADRAAREA LOTE 0002 SALA 1 | R24: PARQUE INDUSTRIAL ARAGUAIA | S24: APARECIDA DE GOIANIA | T24: GO | U24: 74981331 | V24: 62 | W24: 999943525 | X24: Celular | Y24: 62 | Z24: 30859900 | AA24: Fixo | AK24: OSVALDO ANTONIO PAGNUNSSAT ZILLI | AL24: SOCIO ADMINISTRADOR | AM24: 62 | AN24: 984259022 | AO24: VALDIRENE MARIA BEVILAQUA ZILLI | AP24: SOCIO | AQ24: 62 | AR24: 982386633 | AW24: 4511101-Comércio a varejo de automóveis, camionetas e utilitários novos\4511102-Comércio a varejo de automóveis, camionetas e utilitários usados\4511103-Comércio por atacado de automóveis, camionetas e utilitários novos e usados\4511104-Comércio por atacado de caminhões novos e usados\4511105-Comércio por atacado de reboques e semireboques novos e usados\4511106-Comércio por atacado de ônibus e micro-ônibus novos e usados\4512902-Comércio sob consignação de veículos automotores\4661300-Comércio atacadista de máquinas, aparelhos e equipamentos para uso agropecuário, partes e peças\4930201-Transporte rodoviário de carga, exceto produtos perigosos e mudanças, municipal\5211701-Armazéns gerais - emissão de warrant\5211799-Depósitos de mercadorias para terceiros, exceto armazéns gerais e guarda-móveis\5212500-Carga e descarga\5223100-Estacionamento de veículos\5250804-Organização logística do transporte de carga | AX24: 252000137 | AY24: N
A25: 75.813.923/0001-61 | B25: MAGNABOSCO COMERCIO E TRANSPORTES LTDA | C25: TRANS MAGNABOSCO | D25: GRANDE | E25: 211674558 | F25: 158716438 | G25: 498 | H25: 666 | I25: RISCO BAIXO | J25: ATIVA | K25: 4930202 | L25: Transporte rodoviário de carga, exceto produtos perigosos e mudanças, intermunicipal, interestadual e internacional | M25: 3/10/1981 | N25: 10 | O25: SEVERIANO GUERREIRO | P25: 1238 | Q25: R SEVERIANO GUER | R25: CIDADE JARDIM | S25: CATANDUVAS | T25: SC | U25: 89670000 | V25: 49 | W25: 999600033 | X25: Celular | Y25: 49 | Z25: 991611039 | AA25: Celular | AB25: 49 | AC25: 991013927 | AD25: Celular | AE25: 49 | AF25: 35251194 | AG25: Fixo | AH25: CONTASAPAGAR@TRANSMAGNABOSCO.COM.BR | AI25: ALVARO@TRANSMAGNABOSCO.COM.BR | AJ25: ANA@TRANSMAGNABOSCO.COM.BR | AK25: CLODOMAR LUIZ MAGNABOSCO | AL25: ADMINISTRADOR | AM25: 49 | AN25: 999548274 | AO25: MAGNABOSCO PARTICIPACOES LTDA | AP25: SOCIO | AQ25: 49 | AR25: 35251194 | AS25: GUILHERME BORDIN MAGNABOSCO | AT25: ADMINISTRADOR | AU25: 43 | AV25: 998251964 | AW25: 2930101-Fabricação de cabines, carrocerias e reboques para caminhões\4520005-Serviços de lavagem, lubrificação e polimento de veículos automotores\4731800-Comércio varejista de combustíveis para veículos automotores\4929902-Transporte rodoviário coletivo de passageiros, sob regime de fretamento, intermunicipal, interestadual e internacional\4930201-Transporte rodoviário de carga, exceto produtos perigosos e mudanças, municipal\4930203-Transporte rodoviário de produtos perigosos\5212500-Carga e descarga\ | AX25: 250807190 | AY25: N
A26: 03.052.564/0001-66 | B26: TRANS KOTHE TRANSPORTES RODOVIARIOS S/A | C26: KOTHE TRANSPORTES E LOGISTICA | D26: GRANDE | E26: 204078377 | F26: 217622008 | G26: 189 | H26: 913 | I26: RISCO MUITO BAIXO | J26: ATIVA | K26: 4930202 | L26: Transporte rodoviário de carga, exceto produtos perigosos e mudanças, intermunicipal, interestadual e internacional | M26: 3/23/1999 | N26: 22 | O26: JOSE CAPRETZ | P26: 320 | R26: LOTEAMENTO PARQUE INDUSTRIAL | S26: JUNDIAI | T26: SP | U26: 13213095 | V26: 94 | W26: 981691441 | X26: Celular | Y26: 98 | Z26: 981197210 | AA26: Celular | AB26: 94 | AC26: 981694004 | AD26: Celular | AE26: 11 | AF26: 45252629 | AG26: Fixo | AH26: ADILSONTONIELO@KOTHE.COM.BR | AI26: ADIR@KOTHE.COM.BR | AJ26: ADRIANO.GRANDO@KOTHE.COM.BR | AK26: ARLETE KOTHE | AL26: DIRETOR | AM26: 63 | AN26: 992380170 | AO26: ADIR PEDRO KOTHE | AP26: PRESIDENTE | AQ26: 63 | AR26: 992368300 | AS26: ADEMIR KOTHE | AT26: PRESIDENTE | AU26: 11 | AV26: 994612991 | AW26: 4930201-Transporte rodoviário de carga, exceto produtos perigosos e mudanças, municipal\4930203-Transporte rodoviário de produtos perigosos\5211799-Depósitos de mercadorias para terceiros, exceto armazéns gerais e guarda-móveis\5250804-Organização logística do transporte de carga\6463800-Outras sociedades de participação, exceto holdings\ | AX26: 407.578.172.117 | AY26: N
A27: 75.862.821/0001-36 | B27: RODALOG SOLUCOES EM LOGISTICA E TRANSPORTE LTDA | C27: RODALOG | D27: GRANDE | E27: 200838976 | F27: 4000000 | G27: 59 | H27: 492 | I27: RISCO MÉDIO | J27: ATIVA | K27: 4930202 | L27: Transporte rodoviário de carga, exceto produtos perigosos e mudanças, intermunicipal, interestadual e internacional | M27: 3/24/1982 | N27: 10 | O27: ARY SCHOSSLAND | P27: 49 | R27: ANITA GARIBALDI | S27: JOINVILLE | T27: SC | U27: 89202066 | V27: 48 | W27: 991880471 | X27: Celular | Y27: 47 | Z27: 992120267 | AA27: Celular | AB27: 47 | AC27: 992774566 | AD27: Celular | AE27: 47 | AF27: 32786750 | AG27: Fixo | AH27: TRIBUTARIO@RODALOG.COM.BR | AI27: AVILA@RODALOG.COM.BR | AJ27: DEISI.CATARINA@RODALOG.COM.BR | AK27: AUSTERITA PARTICIPACOES LTDA | AL27: SOCIO | AM27: 47 | AN27: 999892622 | AO27: STEFAN RODRIGO SOARES E BOGO | AP27: ADMINISTRADOR | AQ27: 47 | AR27: 999717870 | AW27: 4930201-Transporte rodoviário de carga, exceto produtos perigosos e mudanças, municipal\5211701-Armazéns gerais - emissão de warrant\5211799-Depósitos de mercadorias para terceiros, exceto armazéns gerais e guarda-móveis\5212500-Carga e descarga\5250803-Agenciamento de cargas, exceto para o transporte marítimo\5250804-Organização logística do transporte de carga\5320202-Serviços de entrega rápida\6462000-Holdings de instituições não financeiras\7711000-Locação de automóveis sem condutor\7820500-Locação de mão de obra temporária\7911200-Agências de viagens\8211300-Serviços combinados de escritório e apoio administrativo | AX27: 251798402 | AY27: N
A28: 07.520.001/0001-06 | B28: CARRER ALIMENTOS LTDA EM RECUPERACAO JUDICIAL | D28: GRANDE | E28: 193666534 | F28: 83000000 | G28: 103 | H28: 585 | I28: RISCO BAIXO | J28: ATIVA | K28: 1013901 | L28: Fabricação de produtos de carne | M28: 7/19/2005 | N28: 6 | O28: RSC 453 | Q28: KM 77 DO LADO DA C DE VINHOS | S28: BOA VISTA DO SUL | T28: RS | U28: 95727000 | V28: 51 | W28: 980149662 | X28: Celular | Y28: 54 | Z28: 999215082 | AA28: Celular | AB28: 54 | AC28: 34355426 | AD28: Fixo | AH28: KATIANE@AVICOLACARRER.COM.BR | AK28: HOLDINVEST FOODS S.A. EM RECUPERACAO JUDICIAL | AL28: SOCIO | AM28: 54 | AN28: 30567600 | AO28: GERALDO CARRER | AP28: SOCIO ADMINISTRADOR | AQ28: 54 | AR28: 999943760 | AS28: BRUNO KUMMEL CARRER | AT28: ADMINISTRADOR | AW28: 0155502-Produção de pintos de um dia\0155504-Criação de aves, exceto galináceos\0155505-Produção de ovos\1012101-Abate de aves\1052000-Fabricação de laticínios\1099699-Fabricação de outros produtos alimentícios não especificados anteriormente\4633802-Comércio atacadista de aves vivas e ovos\4634601-Comércio atacadista de carnes bovinas e suínas e derivados\4634602-Comércio atacadista de aves abatidas e derivados\4729699-Comércio varejista de produtos alimentícios em geral ou especializado em produtos alimentícios não especificados anteriormente\4930201-Transporte rodoviário de carga, exceto produtos perigosos e mudanças, municipal\4930202-Transporte rodoviário de carga, exceto produtos perigosos e mudanças, intermunicipal, interestadual e internacional\5211701-Armazéns gerais - emissão de warrant\6810202-Aluguel de imóveis próprios | AX28: 037/0039912 | AY28: N
A29: 22.067.862/0001-74 | B29: CESA S.A. | C29: CESA LOGISTICA | D29: GRANDE | E29: 190665833 | F29: 1000 | H29: 584 | I29: RISCO BAIXO | J29: ATIVA | K29: 4930202 | L29: Transporte rodoviário de carga, exceto produtos perigosos e mudanças, intermunicipal, interestadual e internacional | M29: 10/14/1970 | N29: 1 | O29: DO CONTORNO | P29: 3542 | Q29: SALA 503 | R29: SANTA EFIGENIA | S29: BELO HORIZONTE | T29: MG | U29: 30110018 | V29: 31 | W29: 971031917 | X29: Celular | Y29: 31 | Z29: 997946719 | AA29: Celular | AB29: 31 | AC29: 995203522 | AD29: Celular | AE29: 31 | AF29: 36633500 | AG29: Fixo | AH29: ELDER.CABRAL@CESA.COM.BR | AI29: CESAFISCAL@CESA.COM.BR | AK29: GUSTAVO DIAS | AL29: PRESIDENTE | AM29: 31 | AN29: 999796633 | AO29: MARCELO DIAS | AP29: DIRETOR | AQ29: 31 | AR29: 981159785 | AW29: 4930201-Transporte rodoviário de carga, exceto produtos perigosos e mudanças, municipal\7719599-Locação de outros meios de transporte não especificados anteriormente, sem condutor | AX29: 186030422.00-62 | AY29: S
A30: 78.807.427/0001-93 | B30: COSTA TEIXEIRA TRANSPORTES LTDA | D30: GRANDE | E30: 184223750 | F30: 60000000 | G30: 452 | H30: 449 | I30: RISCO MÉDIO | J30: ATIVA | K30: 4930202 | L30: Transporte rodoviário de carga, exceto produtos perigosos e mudanças, intermunicipal, interestadual e internacional | M30: 7/26/1985 | N30: 13 | O30: BR-376 | Q30: KM499 | R30: COLONIA DONA LUIZA | S30: PONTA GROSSA | T30: PR | U30: 84043450 | V30: 11 | W30: 998740738 | X30: Celular | Y30: 42 | Z30: 40097100 | AA30: Fixo | AH30: NOTAFISCAL@COSTATEIXEIRA.COM.BR | AI30: CLAUDIO.TEIXEIRA@COSTATEIXEIRA.COM.BR | AJ30: CLAUDIO@COSTATEIXEIRA.COM.BR | AK30: CLAUDIO JOSE COSTA TEIXEIRA | AL30: SOCIO ADMINISTRADOR | AM30: 42 | AN30: 999142042 | AO30: GILBERTO LEANDRO COSTA TEIXEIRA | AP30: SOCIO ADMINISTRADOR | AQ30: 41 | AR30: 996195199 | AS30: GILMAR TADEU COSTA TEIXEIRA | AT30: SOCIO ADMINISTRADOR | AU30: 22 | AV30: 981211052 | AW30: 4930201-Transporte rodoviário de carga, exceto produtos perigosos e mudanças, municipal\4930203-Transporte rodoviário de produtos perigosos\5211701-Armazéns gerais - emissão de warrant\5212500-Carga e descarga\5229099-Outras atividades auxiliares dos transportes terrestres não especificadas anteriormente\ | AX30: 20110644-37 | AY30: N
A31: 16.127.441/0001-99 | B31: AVIGRO AVICOLA AGROINDUSTRIAL LTDA | C31: AVIGRO | D31: MÉDIA | E31: 175923925 | F31: 4494000 | G31: 482 | H31: 532 | I31: RISCO BAIXO | J31: ATIVA | K31: 1012101 | L31: Abate de aves | M31: 6/4/1987 | N31: 0 | O31: VILA DOS COQUEIROS | P31: 520 | R31: CENTRO | S31: CONCEICAO DA FEIRA | T31: BA | U31: 44320000 | V31: 75 | W31: 998015976 | X31: Celular | Y31: 75 | Z31: 999416201 | AA31: Celular | AB31: 75 | AC31: 998785571 | AD31: Celular | AE31: 75 | AF31: 32443500 | AG31: Fixo | AH31: GERCONTROLADORIA@AVIGRO.COM.BR | AI31: MARCOS@AVIGRO.COM.BR | AJ31: CLAUDIO@AVIGRO.COM.BR | AK31: MARIA ANTONIA MASCARENHAS ALVES | AL31: SOCIO | AM31: 75 | AN31: 999942024 | AO31: OLINTO PEREIRA ALVES | AP31: SOCIO ADMINISTRADOR | AQ31: 75 | AR31: 981654048 | AS31: LOURIVAL CHAGAS DO NASCIMENTO | AT31: SOCIO | AU31: 75 | AV31: 998038656 | AW31: 0155501-Criação de frangos para corte\0155502-Produção de pintos de um dia\1066000-Fabricação de alimentos para animais\4634601-Comércio atacadista de carnes bovinas e suínas e derivados\4634602-Comércio atacadista de aves abatidas e derivados\4712100-Comércio varejista de mercadorias em geral, com predominância de produtos alimentícios - minimercados, mercearias e armazéns\4722901-Comércio varejista de carnes - açougues\4729602-Comércio varejista de mercadorias em lojas de conveniência\4729699-Comércio varejista de produtos alimentícios em geral ou especializado em produtos alimentícios não especificados anteriormente\4930202-Transporte rodoviário de carga, exceto produtos perigosos e mudanças, intermunicipal, interestadual e internacional | AX31: 026.152.167 | AY31: N
A32: 60.678.471/0001-85 | B32: LEPE INDUSTRIA E COMERCIO LTDA | D32: MÉDIA | E32: 172951394 | F32: 3100000 | G32: 411 | H32: 902 | I32: RISCO MUITO BAIXO | J32: ATIVA | K32: 2451200 | L32: Fundição de ferro e aço | M32: 10/6/1966 | N32: 0 | O32: LUIS RODRIGUES DE FREITAS | P32: 597 | R32: VILA ROSA MINELIA | S32: GUARULHOS | T32: SP | U32: 7034050 | V32: 11 | W32: 964757070 | X32: Celular | Y32: 11 | Z32: 974180268 | AA32: Celular | AB32: 11 | AC32: 942952223 | AD32: Celular | AE32: 11 | AF32: 24757091 | AG32: Fixo | AH32: CONTABIL@LEPE.COM.BR | AI32: COMPRAS@LEPE.COM.BR | AJ32: ACK@LEPE.COM.BR | AK32: ANTONIO CARLOS KOCH | AL32: SOCIO ADMINISTRADOR | AM32: 11 | AN32: 969764256 | AO32: AUGUSTO KOCH JUNIOR | AP32: SOCIO ADMINISTRADOR | AQ32: 11 | AR32: 978156406 | AS32: LUIZ CARLOS KOCH | AT32: SOCIO ADMINISTRADOR | AU32: 11 | AV32: 999826475 | AX32: 336.066.110.115 | AY32: N
A33: 03.875.931/0001-21 | B33: NEPOMUCENO CARGAS LTDA. | C33: NEPOMUCENO LOGISTICA | D33: GRANDE | E33: 162598033 | F33: 45351208 | G33: 181 | H33: 576 | I33: RISCO BAIXO | J33: ATIVA | K33: 4930202 | L33: Transporte rodoviário de carga, exceto produtos perigosos e mudanças, intermunicipal, interestadual e internacional | M33: 6/9/2000 | N33: 8 | O33: DOM GABRIEL PAULINO BUENO COUTO | P33: 500 | Q33: SALA 4 PREDIO A | R33: MEDEIROS | S33: JUNDIAI | T33: SP | U33: 13212240 | V33: 35 | W33: 36949837 | X33: Fixo | AH33: NEPOMUCENOCARGASLTDA@GMAIL.COM | AI33: CPEDROSO@EXPRESSONEPOMUCENO.COM.BR | AJ33: ADRIANOCARDOSO@EXPRESSONEPOMUCENO.COM.BR | AK33: EXPRESSO NEPOMUCENO S/A | AL33: SOCIO | AM33: 35 | AN33: 998164753 | AO33: AGNALDO DE SOUZA FILHO | AP33: ADMINISTRADOR | AQ33: 35 | AR33: 988577625 | AS33: AGNESIO CARVALHO DE SOUZA NETO | AT33: ADMINISTRADOR | AU33: 35 | AV33: 988328195 | AW33: 4520001-Serviços de manutenção e reparação mecânica de veículos automotores\4930201-Transporte rodoviário de carga, exceto produtos perigosos e mudanças, municipal\4930203-Transporte rodoviário de produtos perigosos\5211799-Depósitos de mercadorias para terceiros, exceto armazéns gerais e guarda-móveis\5212500-Carga e descarga\5250804-Organização logística do transporte de carga\5320202-Serviços de entrega rápida\6810202-Aluguel de imóveis próprios\7711000-Locação de automóveis sem condutor\7719599-Locação de outros meios de transporte não especificados anteriormente, sem condutor\7739099-Aluguel de outras máquinas e equipamentos comerciais e industriais não especificados anteriormente, sem operador\7820500-Locação de mão de obra temporária | AX33: 407.744.676.118 | AY33: N
A34: 06.292.402/0001-93 | B34: BRAMETAL MG METALURGICA LTDA | C34: BRAMETAL MG | D34: MÉDIA | E34: 161477780 | F34: 37400000 | G34: 5 | H34: 588 | I34: RISCO BAIXO | J34: ATIVA | K34: 2511000 | L34: Fabricação de estruturas metálicas | M34: 6/4/2004 | N34: 0 | O34: DO CONTORNO 2905 | P34: 2905 | Q34: ANDAR 4 | R34: SANTA EFIGENIA | S34: BELO HORIZONTE | T34: MG | U34: 30110915 | V34: 31 | W34: 971263708 | X34: Celular | Y34: 31 | Z34: 999637354 | AA34: Celular | AB34: 31 | AC34: 995190762 | AD34: Celular | AE34: 27 | AF34: 21039051 | AG34: Fixo | AH34: CONTROLADORIA@BRAMETAL.COM.BR | AI34: CINTIA@BRAMETAL.COM.BR | AJ34: ADRIANA.SMARSARO@BRAMETAL.COM.BR | AK34: HOLLMORE PARTICIPACOES E INVESTIMENTOS LTDA | AL34: SOCIO | AO34: RICARDO MINATTO BRANDAO | AP34: SOCIO | AQ34: 48 | AR34: 991716600 | AS34: ALEXANDRE QUEIROZ SCHMIDT | AT34: ADMINISTRADOR | AU34: 27 | AV34: 988004321 | AW34: 2330302-Fabricação de artefatos de cimento para uso na construção\2539001-Serviços de usinagem, torneiria e solda\2539002-Serviços de tratamento e revestimento em metais\4110700-Incorporação de empreendimentos imobiliários\4292801-Montagem de estruturas metálicas\4292802-Obras de montagem industrial\4689399-Comércio atacadista especializado em outros produtos intermediários não especificados anteriormente\4744005-Comércio varejista de materiais de construção não especificados anteriormente\4744099-Comércio varejista de materiais de construção em geral\7112000-Serviços de engenharia | AX34: 567295995.00-09 | AY34: N
A35: 04.662.776/0001-28 | B35: CAJURU INDUSTRIA E COMERCIO DE ALIMENTOS LTDA EM RECUPERACAO JUDICIAL | D35: MÉDIA | E35: 157755862 | F35: 4400000 | G35: 108 | H35: 577 | I35: RISCO BAIXO | J35: ATIVA | K35: 1013901 | L35: Fabricação de produtos de carne | M35: 9/14/2001 | N35: 0 | O35: JONAS JACOB SANTANA | P35: 85 | Q35: 16 3667 9000 PRQ INDUS | R35: DIST INDUSTRIAL I | S35: CAJURU | T35: SP | U35: 14240000 | V35: 16 | W35: 991323616 | X35: Celular | Y35: 16 | Z35: 993208861 | AA35: Celular | AB35: 16 | AC35: 991425829 | AD35: Celular | AE35: 16 | AF35: 36679000 | AG35: Fixo | AH35: GOLDMEAT@GOLDMEAT.COM.BR | AK35: JOSE PAULO CANDIDO JUNIOR | AL35: SOCIO ADMINISTRADOR | AM35: 16 | AN35: 991160012 | AO35: SILVIA MARIA LOPES DA SILVA CARDINALI CANDIDO | AP35: SOCIO ADMINISTRADOR | AQ35: 16 | AR35: 997941231 | AW35: 4619200-Representantes comerciais e agentes do comércio de mercadorias em geral não especializado\4631100-Comércio atacadista de leite e laticínios\4634601-Comércio atacadista de carnes bovinas e suínas e derivados\4634602-Comércio atacadista de aves abatidas e derivados\4634603-Comércio atacadista de pescados e frutos do mar\4637199-Comércio atacadista especializado em outros produtos alimentícios não especificados anteriormente\4642702-Comércio atacadista de roupas e acessórios para uso profissional e de segurança do trabalho\4721103-Comércio varejista de laticínios e frios | AX35: 243.065.620.112 | AY35: S
A36: 11.270.328/0001-44 | B36: BOVMEAT PROCESSADORA DE CARNES E DERIVADOS LTDA. | C36: BOVMEAT CARNES | D36: MÉDIA | E36: 152021534 | F36: 3020000 | G36: 269 | H36: 875 | I36: RISCO MUITO BAIXO | J36: ATIVA | K36: 1013901 | L36: Fabricação de produtos de carne | M36: 7/31/2009 | N36: 1 | O36: PRACA BERNARDINO DE CAMPOS 184 | Q36: GALPAOINDUSTRIAL | R36: CENTRO | S36: ITAPIRA | T36: SP | U36: 13970970 | V36: 19 | W36: 992079256 | X36: Celular | Y36: 19 | Z36: 989788982 | AA36: Celular | AB36: 19 | AC36: 992945469 | AD36: Celular | AE36: 19 | AF36: 38632354 | AG36: Fixo | AH36: ALESSANDROALMEIDA@BOVMEAT.COM.BR | AI36: ALEX@BOVMEAT.COM.BR | AJ36: DELSON@BOVMEAT.COM.BR | AK36: ALESSANDRO SAMPAIO DE ALMEIDA | AL36: SOCIO ADMINISTRADOR | AM36: 19 | AN36: 992945509 | AO36: PATRICIA PEREIRA SOARES DE ALMEIDA | AP36: SOCIO ADMINISTRADOR | AQ36: 19 | AR36: 992945509 | AW36: 4617600-Representantes comerciais e agentes do comércio de produtos alimentícios, bebidas e fumo\4631100-Comércio atacadista de leite e laticínios\4637199-Comércio atacadista especializado em outros produtos alimentícios não especificados anteriormente\4691500-Comércio atacadista de mercadorias em geral, com predominância de produtos alimentícios | AX36: 374.136.362.111 | AY36: N
A37: 36.492.502/0001-24 | B37: CHARQUE 500 INDUSTRIA E COMERCIO LTDA | D37: MÉDIA | E37: 149507150 | F37: 918000 | G37: 225 | H37: 504 | I37: RISCO BAIXO | J37: ATIVA | K37: 1013901 | L37: Fabricação de produtos de carne | M37: 4/25/1991 | N37: 2 | O37: JOAQUIM EUGENIO SANTOS | P37: 500 | R37: CENTRO | S37: MARICA | T37: RJ | U37: 24901040 | V37: 21 | W37: 990118593 | X37: Celular | Y37: 21 | Z37: 983680122 | AA37: Celular | AB37: 21 | AC37: 983680175 | AD37: Celular | AE37: 21 | AF37: 26372326 | AG37: Fixo | AH37: CLEIDI@CHARQUE500.COM.BR | AI37: CARLOS@CHARQUE500.COM.BR | AJ37: CATIA@CHARQUE500.COM.BR | AK37: WALTER ROBERTO COLAVITTI | AL37: SOCIO ADMINISTRADOR | AM37: 21 | AN37: 988302326 | AO37: CLEIDI DA SILVA ABREU | AP37: SOCIO | AQ37: 21 | AR37: 979258911 | AW37: 4639702-Comércio atacadista de produtos alimentícios em geral, com atividade de fracionamento e acondicionamento associada\4721103-Comércio varejista de laticínios e frios\4722901-Comércio varejista de carnes - açougues\4930202-Transporte rodoviário de carga, exceto produtos perigosos e mudanças, intermunicipal, interestadual e internacional\8292000-Envasamento e empacotamento sob contrato\ | AX37: 84.000.418 | AY37: S
A38: 03.836.990/0001-90 | B38: CPA ARMAZENS GERAIS LTDA | D38: MÉDIA | E38: 144050393 | F38: 75225608 | G38: 26 | H38: 775 | I38: RISCO MUITO BAIXO | J38: ATIVA | K38: 5211701 | L38: Armazéns gerais - emissão de warrant | M38: 5/25/2000 | N38: 1 | O38: CASTELO BRANCO | P38: 800 | Q38: SALA02LOTE199 A | R38: VERA CRUZ | S38: SARANDI | T38: PR | U38: 87111760 | V38: 44 | W38: 991621621 | X38: Celular | Y38: 44 | Z38: 991341846 | AA38: Celular | AB38: 44 | AC38: 991169613 | AD38: Celular | AE38: 44 | AF38: 32888001 | AG38: Fixo | AH38: GILBERTO@CPATRADING.COM.BR | AK38: PAULO MENEGUETTI | AL38: ADMINISTRADOR | AM38: 44 | AN38: 999821982 | AO38: CPA HOLDING PARTICIPACOES S.A. | AP38: SOCIO | AQ38: 44 | AR38: 32888000 | AS38: AYRTON CARLOS BERG JUNIOR | AT38: ADMINISTRADOR | AU38: 44 | AV38: 999645015 | AW38: 3315500-Manutenção e reparação de veículos ferroviários\4619200-Representantes comerciais e agentes do comércio de mercadorias em geral não especializado\5231102-Atividades do Operador Portuário\5250802-Atividades de despachantes aduaneiros\5250804-Organização logística do transporte de carga\8211300-Serviços combinados de escritório e apoio administrativo | AY38: N
A39: 60.746.518/0001-09 | B39: TRANSPORTADORA TRANSLECCHI LTDA | C39: TRANSLECCHI | D39: GRANDE | E39: 135876829 | F39: 7355820 | H39: 703 | I39: RISCO MUITO BAIXO | J39: ATIVA | K39: 4930202 | L39: Transporte rodoviário de carga, exceto produtos perigosos e mudanças, intermunicipal, interestadual e internacional | M39: 6/7/1989 | N39: 5 | O39: PAULISTA | P39: 1636 | Q39: CONJ8 PAV 13 | R39: BELA VISTA | S39: SAO PAULO | T39: SP | U39: 01310200 | V39: 11 | W39: 999771076 | X39: Celular | Y39: 11 | Z39: 47904790 | AA39: Fixo | AH39: CLAUDENIR.MENDES@TRANSLECCHI.COM.BR | AI39: WEBMASTER@TRANSLECCHI.COM.BR | AJ39: WAGNER.DIAS@TRANSLECCHI.COM.BR | AK39: ROBERTO GIUSEPPE MONGUZZI | AL39: SOCIO ADMINISTRADOR | AM39: 11 | AN39: 999771076 | AO39: ALDO ERNESTO MONGUZZI | AP39: SOCIO ADMINISTRADOR | AQ39: 62 | AR39: 995027871 | AW39: 5212500-Carga e descarga\5250804-Organização logística do transporte de carga\7739099-Aluguel de outras máquinas e equipamentos comerciais e industriais não especificados anteriormente, sem operador\ | AX39: 140.798.820.111 | AY39: N
A40: 08.247.312/0001-06 | B40: TECER - TERMINAIS PORTUARIOS CEARA LTDA | D40: MÉDIA | E40: 132943988 | F40: 1300000 | G40: 471 | H40: 533 | I40: RISCO BAIXO | J40: ATIVA | K40: 5231102 | L40: Atividades do Operador Portuário | M40: 7/26/2006 | N40: 2 | O40: S LUIS | P40: 671 | R40: CENTRO | S40: PECEM | T40: CE | U40: 62674000 | V40: 85 | W40: 981744236 | X40: Celular | Y40: 85 | Z40: 981243183 | AA40: Celular | AB40: 85 | AC40: 981769949 | AD40: Celular | AE40: 85 | AF40: 33151415 | AG40: Fixo | AH40: CONTABILIDADE@TECERTERMINAIS.COM.BR | AK40: BERTRAND ALPHONSE BORIS NETO | AL40: ADMINISTRADOR | AM40: 85 | AN40: 999812988 | AO40: TERMACO PARTICIPACOES S.A. | AP40: SOCIO | AQ40: 85 | AR40: 33885600 | AS40: TOME PARTICIPACOES LTDA (EM RECUPERACAO JUDICIAL) | AT40: SOCIO | AU40: 11 | AV40: 43556254 | AW40: 4520001-Serviços de manutenção e reparação mecânica de veículos automotores\4520002-Serviços de lanternagem ou funilaria e pintura de veículos automotores\4520005-Serviços de lavagem, lubrificação e polimento de veículos automotores\4520006-Serviços de borracharia para veículos automotores\5212500-Carga e descarga\5231101-Administração da infraestrutura portuária\5250804-Organização logística do transporte de carga\7739099-Aluguel de outras máquinas e equipamentos comerciais e industriais não especificados anteriormente, sem operador | AX40: 06.199520-7 | AY40: N
A41: 06.106.950/0001-81 | B41: YUSEN LOGISTICS DO BRASIL LTDA. | C41: YUSEN LOGISTICS DO BRASIL | D41: GRANDE | E41: 128261120 | F41: 66664900 | G41: 127 | H41: 489 | I41: RISCO MÉDIO | J41: ATIVA | K41: 5211701 | L41: Armazéns gerais - emissão de warrant | M41: 12/16/2003 | N41: 17 | O41: ANHANGUERA KM 15 | Q41: GALPAO1 PARTE E 2 | R41: VILA JAGUARA | S41: SAO PAULO | T41: SP | U41: 5113902 | V41: 11 | W41: 972679882 | X41: Celular | Y41: 11 | Z41: 974911741 | AA41: Celular | AB41: 11 | AC41: 934720135 | AD41: Celular | AE41: 11 | AF41: 39089700 | AG41: Fixo | AH41: YLBR.FISCAL@BR.YUSEN-LOGISTICS.COM | AI41: ADRIANA.ROVIGATTI@BR.YUSEN-LOGISTICS.COM | AJ41: MARGARIDA.PLACIDIO@BR.YUSEN-LOGISTICS.COM | AK41: YUSEN LOGISTICS CO., LTDA | AL41: SOCIO PESSOA JURIDICA DOMICILIADO NO EXTERIOR | AO41: EDSON TADAO CHIKU | AP41: ADMINISTRADOR | AQ41: 11 | AR41: 964458842 | AW41: 4930202-Transporte rodoviário de carga, exceto produtos perigosos e mudanças, intermunicipal, interestadual e internacional\5232000-Atividades de agenciamento marítimo\5250802-Atividades de despachantes aduaneiros\5250803-Agenciamento de cargas, exceto para o transporte marítimo\5250804-Organização logística do transporte de carga\5250805-Operador de transporte multimodal - OTM\9512600-Reparação e manutenção de equipamentos de comunicação\ | AX41: 116.765.606.111 | AY41: N
...

Sheet ADRIANA
A1: Carteira de Prospects — Vendedor 2
A2: Total de empresas: 47 | Porte: GRANDE | Fonte: Base de prospecção
A4: CNPJ | B4: Razão Social | C4: Nome Fantasia | D4: Porte | E4: Faturamento Presumido (R$) | F4: Capital Social (R$) | G4: Qtd. Funcionários | H4: Score | I4: Classificação de Risco | J4: Situação Cadastral | K4: CNAE | L4: Atividade Principal | M4: Data Abertura | N4: Qtd. Filiais | O4: Logradouro | P4: Nº | Q4: Complemento | R4: Bairro | S4: Cidade | T4: UF | U4: CEP | V4: DDD 1 | W4: Telefone 1 | X4: Tipo 1 | Y4: DDD 2 | Z4: Telefone 2 | AA4: Tipo 2 | AB4: DDD 3 | AC4: Telefone 3 | AD4: Tipo 3 | AE4: DDD 4 | AF4: Telefone 4 | AG4: Tipo 4 | AH4: E-mail 1 | AI4: E-mail 2 | AJ4: E-mail 3 | AK4: Sócio 1 | AL4: Cargo Sócio 1 | AM4: DDD Sócio 1 | AN4: Tel. Sócio 1 | AO4: Sócio 2 | AP4: Cargo Sócio 2 | AQ4: DDD Sócio 2 | AR4: Tel. Sócio 2 | AS4: Sócio 3 | AT4: Cargo Sócio 3 | AU4: DDD Sócio 3 | AV4: Tel. Sócio 3 | AW4: CNAEs Secundários | AX4: Inscrição Estadual | AY4: Flag DAU
A5: 61.752.739/0001-44 | B5: PRIETO ALIMENTOS LTDA EM RECUPERACAO JUDICIAL | D5: GRANDE | E5: 468405686 | F5: 3100000 | G5: 313 | H5: 410 | I5: RISCO MÉDIO | J5: ATIVA | K5: 1013901 | L5: Fabricação de produtos de carne | M5: 12/5/1972 | N5: 1 | O5: VEREADOR JOAQUIM PEREIRA BARBOSA | P5: 777 | R5: JORDANESIA (JORDANESIA) | S5: CAJAMAR | T5: SP | U5: 7776450 | V5: 16 | W5: 997669806 | X5: Celular | Y5: 11 | Z5: 950578821 | AA5: Celular | AB5: 19 | AC5: 981818143 | AD5: Celular | AE5: 11 | AF5: 48988106 | AG5: Fixo | AH5: PATRICIA.AVILA@PRIETOALIMENTOS.COM.BR | AI5: NATASHA@FRIGORIFICOPRIETO.COM.BR | AJ5: KEDMA@FRIGORIFICOPRIETO.COM.BR | AK5: MARCO AURELIO DA CRUZ VILLARINO PRIETO | AL5: DIRETOR | AM5: 11 | AN5: 996136190 | AO5: MARCELO DA CRUZ VILLARINO PRIETO | AP5: DIRETOR | AQ5: 19 | AR5: 996135780 | AW5: 4619200-Representantes comerciais e agentes do comércio de mercadorias em geral não especializado\4930202-Transporte rodoviário de carga, exceto produtos perigosos e mudanças, intermunicipal, interestadual e internacional\6821802-Corretagem no aluguel de imóveis\ | AX5: 241.003.423.118 | AY5: N
A6: 52.764.354/0001-06 | B6: TEC VIDRO INDUSTRIA, COMERCIO E SERVICOS TECNICOS S.A. | D6: GRANDE | E6: 431301757 | F6: 5120000 | G6: 19 | H6: 889 | I6: RISCO MUITO BAIXO | J6: ATIVA | K6: 4713002 | L6: Lojas de variedades, exceto lojas de departamentos ou magazines | M6: 7/28/1983 | N6: 1 | O6: VENUS | P6: 582 | Q6: SALA 01 | R6: AMERICAN PARK EMPRESARIAL NR | S6: INDAIATUBA | T6: SP | U6: 13347659 | V6: 11 | W6: 989838293 | X6: Celular | Y6: 11 | Z6: 991020112 | AA6: Celular | AB6: 11 | AC6: 975998936 | AD6: Celular | AE6: 19 | AF6: 39355454 | AG6: Fixo | AH6: TECVIDRO@TECVIDRO.COM.BR | AK6: GERMANO TOLEDO WEGBECHER | AL6: DIRETOR | AO6: VINICIUS NUNES BRAGA | AP6: DIRETOR | AQ6: 11 | AR6: 999661035 | AW6: 8211300-Serviços combinados de escritório e apoio administrativo\ | AX6: 110.941.280.116 | AY6: N
A7: 83.491.985/0001-22 | B7: SECCIONAL BRASIL SA | C7: SECCIONAL | D7: GRANDE | E7: 415840903 | F7: 6597456 | G7: 61 | H7: 913 | I7: RISCO MUITO BAIXO | J7: ATIVA | K7: 2511000 | L7: Fabricação de estruturas metálicas | M7: 7/27/1977 | N7: 0 | O7: JUSCELINO KUBITSCHEK DE OLIVEIRA | P7: 4225 | R7: CIDADE INDUSTRIAL | S7: CURITIBA | T7: PR | U7: 81270200 | V7: 41 | W7: 992694931 | X7: Celular | Y7: 41 | Z7: 33172270 | AA7: Fixo | AB7: 41 | AC7: 995260027 | AD7: Celular | AH7: INFORME@SECCIONAL.COM.BR | AI7: PAULA@SECCIONAL.COM.BR | AJ7: ANA@SECCIONAL.COM.BR | AK7: PAULO EMMANUEL DE ABREU JUNIOR | AL7: PRESIDENTE | AM7: 41 | AN7: 999734968 | AO7: PEDRO GUSTAVO ARAUJO DE ABREU | AP7: DIRETOR | AQ7: 41 | AR7: 999642860 | AS7: ANA CRISTINA ARAUJO DE ABREU MICHELENA | AT7: DIRETOR | AU7: 41 | AV7: 991549262 | AW7: 4292801-Montagem de estruturas metálicas\6462000-Holdings de instituições não financeiras\6810201-Compra e venda de imóveis próprios\6810202-Aluguel de imóveis próprios\7112000-Serviços de engenharia\7210000-Pesquisa e desenvolvimento experimental em ciências físicas e naturais\7739099-Aluguel de outras máquinas e equipamentos comerciais e industriais não especificados anteriormente, sem operador\7740300-Gestão de ativos intangíveis não financeiros | AX7: 10166115-61 | AY7: N
A8: 07.522.140/0001-79 | B8: NITSHORE ENGENHARIA E SERVICOS PORTUARIOS S.A. | D8: GRANDE | E8: 407301183 | F8: 31884406 | G8: 78 | H8: 701 | I8: RISCO MUITO BAIXO | J8: ATIVA | K8: 5231102 | L8: Atividades do Operador Portuário | M8: 8/1/2005 | N8: 1 | O8: FELICIANO SODRE | P8: 215 | Q8: 325 | R8: CENTRO | S8: NITEROI | T8: RJ | U8: 24030012 | V8: 21 | W8: 972202462 | X8: Celular | Y8: 21 | Z8: 999043580 | AA8: Celular | AB8: 21 | AC8: 995192149 | AD8: Celular | AE8: 21 | AF8: 21012250 | AG8: Fixo | AH8: MARIO.BARRETO@NITSHORE.COM.BR | AI8: ANDREA.MONTEIRO@NITSHORE.COM.BR | AJ8: COMPRAS@NITSHORE.COM.BR | AK8: GILSON GONCALVES RIBEIRO JUNIOR | AL8: CONSELHEIRO DE ADMINISTRACAO | AO8: WILSON ROBERTO COUTINHO | AP8: CONSELHEIRO DE ADMINISTRACAO | AW8: 3811400-Coleta de resíduos não perigosos\3812200-Coleta de resíduos perigosos\5211799-Depósitos de mercadorias para terceiros, exceto armazéns gerais e guarda-móveis\5212500-Carga e descarga\5239799-Atividades auxiliares dos transportes aquaviários não especificadas anteriormente\ | AX8: 77.980.326 | AY8: N
A9: 07.464.123/0001-22 | B9: MAFRIAL MATADOURO E FRIGORIFICO LTDA | D9: GRANDE | E9: 390411936 | F9: 200000 | G9: 23 | H9: 266 | I9: RISCO ALTO | J9: ATIVA | K9: 1011201 | L9: Frigorífico - abate de bovinos | M9: 6/10/2005 | N9: 0 | O9: SINVAL RODRIGUES COELHO | P9: 261 | R9: VILA ISA | S9: GOVERNADOR VALADARES | T9: MG | U9: 35044380 | V9: 33 | W9: 991237628 | X9: Celular | Y9: 33 | Z9: 991237508 | AA9: Celular | AB9: 33 | AC9: 991237737 | AD9: Celular | AE9: 33 | AF9: 32788587 | AG9: Fixo | AH9: CICERO.SILVA@MAFRIAL.COM.BR | AI9: JUSCELINO@MAFRIAL.COM.BR | AK9: JUSCELINO FARIA LOPES | AL9: SOCIO ADMINISTRADOR | AM9: 33 | AN9: 999897766 | AW9: 1012103-Frigorífico - abate de suínos\1013901-Fabricação de produtos de carne\1013902-Preparação de subprodutos do abate\4634601-Comércio atacadista de carnes bovinas e suínas e derivados\4722901-Comércio varejista de carnes - açougues\4723700-Comércio varejista de bebidas\4789099-Comércio varejista de outros produtos não especificados anteriormente\ | AX9: 277377294.00-07 | AY9: N
